Workbook
Name dr: [2]DCF!$E$18
Name tg: [2]DCF!$E$19
Name tgr: [3]DCF!$E$19
Name tgr: [4]DCF!$E$19
Name wacc: [3]DCF!$E$18
Name wacc: [4]DCF!$E$18

Sheet DCF
B2: DCF
B4: Ticker | C4: GOOGL | E4: Current Stock Price
B5: Date | C5: 46045 | E5: Implied Share Price
B6: Year End | C6: 46387 | E6: Upside/ (Downside)
A8: x | B8: Assumptions
B10: Switches | G10: Conservative | L10: Base | Q10: Optimistic
B11: Assumptions | G11: Assumptions | I11: Year | J11: Metric | L11: Assumptions | N11: Year | O11: Metric | Q11: Assumptions | S11: Year | T11: Metric
B12: Revenue | E12: 1 | G12: Revenue (% of street) | I12: '26-'27 | J12: 0.95 | Q12: Revenue (% of street) | S12: '26-'27 | T12: 1.05
B13: EBIT | E13: 1 | G13: Revenue Decel | I13: '28-'30 | J13: -0.1 | L13: Revenue Decel | N13: '28-'30 | O13: -0.075 | Q13: Revenue Decel | S13: '28-'30 | T13: -0.05
B14: WACC | E14: 1 | G14: EBIT (% of street) | I14: '26-'27 | J14: 0.95 | Q14: EBIT (% of street) | S14: '26-'27 | T14: 1.05
B15: TGR | E15: 1 | G15: EBIT Margin Target | I15: '30 | J15: 0.345 | L15: EBIT Margin Target | N15: '30 | O15: 0.36 | Q15: EBIT Margin Target | S15: '30 | T15: 0.375
B17: Valuation
B18: WACC | E18: =CHOOSE(E14,J18,O18,T18) -> 0.090910262 | G18: WACC | J18: =O18+0.5% -> 0.090910262 | L18: WACC | O18: =WACC!F22 -> 0.085910262 | Q18: WACC | T18: =O18-0.5% -> 0.080910262
B19: TGR | E19: =CHOOSE(E15,J19,O19,T19) -> 0.02 | G19: TGR | J19: 0.02 | L19: TGR | O19: 0.025 | Q19: TGR | T19: 0.03
B21: Cash Flow
B22: D&A 2030 Target | E22: 0.12
B23: CapEx 2030 Target | E23: 0.18
A25: x | B25: Income Statement (12/31) | E25: 2019 | F25: =E25+1 -> 2020 | G25: =F25+1 -> 2021 | H25: =G25+1 -> 2022 | I25: =H25+1 -> 2023 | J25: =I25+1 -> 2024 | K25: =J25+1 -> 2025 | L25: =K25+1 -> 2026 | M25: =L25+1 -> 2027 | ... O25: =N25+1 -> 2029
B26: Revenue | E26: ='IS - Historical'!F10 -> 161857 | F26: ='IS - Historical'!G10 -> 182527 | G26: ='IS - Historical'!H10 -> 257637 | H26: ='IS - Historical'!I10 -> 282836 | I26: ='IS - Historical'!J10 -> 307394 | J26: ='IS - Historical'!K10 -> 350018 | K26: ='IS - Estimates'!H5 -> 400240 | L26: ='IS - Estimates'!I5 -> 457333 | M26: ='IS - Estimates'!J5 -> 517597 | N26: ='IS - Estimates'!K5 -> 583105 | O26: ='IS - Estimates'!L5 -> 643579
B27: % growth | F27: =F26/E26-1 -> 0.12770532 | G27: =G26/F26-1 -> 0.41150076 | H27: =H26/G26-1 -> 0.097808156 | I27: =I26/H26-1 -> 0.086827702 | J27: =J26/I26-1 -> 0.13866243 | K27: =K26/J26-1 -> 0.14348405 | L27: =L26/K26-1 -> 0.14264691 | M27: =M26/L26-1 -> 0.13177269 | ... O27: =O26/N26-1 -> 0.10371031
B29: EBIT | E29: ='IS - Historical'!F23 -> 34231 | F29: ='IS - Historical'!G23 -> 41224 | G29: ='IS - Historical'!H23 -> 78714 | H29: ='IS - Historical'!I23 -> 74842 | I29: ='IS - Historical'!J23 -> 84293 | J29: ='IS - Historical'!K23 -> 112390 | K29: ='IS - Estimates'!H9 -> 130555 | L29: ='IS - Estimates'!I9 -> 153756 | M29: ='IS - Estimates'!J9 -> 179174 | N29: ='IS - Estimates'!K9 -> 204405 | O29: ='IS - Estimates'!L9 -> 232058
B30: % of sales | E30: =E29/E26 -> 0.21148915 | F30: =F29/F26 -> 0.22585152 | G30: =G29/G26 -> 0.30552289 | H30: =H29/H26 -> 0.26461271 | I30: =I29/I26 -> 0.2742181 | J30: =J29/J26 -> 0.32109777 | K30: =K29/K26 -> 0.32619178 | L30: =L29/L26 -> 0.33620141 | ... O30: =O29/O26 -> 0.36057423
B32: Taxes | E32: =-'IS - Historical'!F27 -> 5282 | F32: =-'IS - Historical'!G27 -> 7813 | G32: =-'IS - Historical'!H27 -> 14701 | H32: =-'IS - Historical'!I27 -> 11356 | I32: =-'IS - Historical'!J27 -> 11922 | J32: =-'IS - Historical'!K27 -> 19697
B33: Tax rate | E33: =-'IS - Historical'!F27/'IS - Historical'!F26 -> 0.13329968 | F33: =-'IS - Historical'!G27/'IS - Historical'!G26 -> 0.16249324 | G33: =-'IS - Historical'!H27/'IS - Historical'!H26 -> 0.16202306 | H33: =-'IS - Historical'!I27/'IS - Historical'!I26 -> 0.15920817 | I33: =-'IS - Historical'!J27/'IS - Historical'!J26 -> 0.1390856 | J33: =-'IS - Historical'!K27/'IS - Historical'!K26 -> 0.16439511
A35: x | B35: Cash Flow Items (12/31) | E35: 2019 | F35: =E35+1 -> 2020 | G35: =F35+1 -> 2021 | H35: =G35+1 -> 2022 | I35: =H35+1 -> 2023 | J35: =I35+1 -> 2024 | K35: =J35+1 -> 2025 | L35: =K35+1 -> 2026 | M35: =L35+1 -> 2027 | ... O35: =N35+1 -> 2029
B36: D&A | E36: ='CFS - Historicals'!F13 -> 10856 | F36: ='CFS - Historicals'!G13 -> 12905 | G36: ='CFS - Historicals'!H13 -> 11555 | H36: ='CFS - Historicals'!I13 -> 15287 | I36: ='CFS - Historicals'!J13 -> 11946 | J36: ='CFS - Historicals'!K13 -> 15311 | K36: ='CFS - Estimates'!H12 -> 21703 | L36: ='CFS - Estimates'!I12 -> 30959.5 | M36: ='CFS - Estimates'!J12 -> 42393.9 | N36: ='CFS - Estimates'!K12 -> 58174.5 | O36: ='CFS - Estimates'!L12 -> 74564.1
B37: % of sales | E37: =E36/E26 -> 0.067071551 | F37: =F36/F26 -> 0.070701869 | G37: =G36/G26 -> 0.044849925 | H37: =H36/H26 -> 0.05404899 | I37: =I36/I26 -> 0.038862177 | J37: =J36/J26 -> 0.043743465 | K37: =K36/K26 -> 0.054224965 | L37: =L36/L26 -> 0.067695749 | ... O37: =O36/O26 -> 0.1158585
B39: CapEx | E39: =-'CFS - Historicals'!F38 -> 22959 | F39: =-'CFS - Historicals'!G38 -> 22213 | G39: =-'CFS - Historicals'!H38 -> 24099 | H39: =-'CFS - Historicals'!I38 -> 29896 | I39: =-'CFS - Historicals'!J38 -> 33302 | J39: =-'CFS - Historicals'!K38 -> 55202 | K39: ='CFS - Estimates'!H5 -> 89125.8 | L39: ='CFS - Estimates'!I5 -> 115437 | M39: ='CFS - Estimates'!J5 -> 131411 | N39: ='CFS - Estimates'!K5 -> 137222 | O39: ='CFS - Estimates'!L5 -> 140447
B40: % of sales | E40: =E39/E26 -> 0.14184743 | F40: =F39/F26 -> 0.12169706 | G40: =G39/G26 -> 0.093538583 | H40: =H39/H26 -> 0.10570083 | I40: =I39/I26 -> 0.10833653 | J40: =J39/J26 -> 0.15771189 | K40: =K39/K26 -> 0.22268089 | L40: =L39/L26 -> 0.25241345 | ... O40: =O39/O26 -> 0.21822807
B42: Change in NWC | E42: ='CFS - Historicals'!F27 -> 819 | F42: ='CFS - Historicals'!G27 -> 1827 | G42: ='CFS - Historicals'!H27 -> -1523 | H42: ='CFS - Historicals'!I27 -> -2235 | I42: ='CFS - Historicals'!J27 -> -3845 | J42: ='CFS - Historicals'!K27 -> -8406
B43: % of sales | E43: =E42/E26 -> 0.0050600221 | F43: =F42/F26 -> 0.010009478 | G43: =G42/G26 -> -0.005911418 | H43: =H42/H26 -> -0.0079021058 | I43: =I42/I26 -> -0.012508377 | J43: =J42/J26 -> -0.024015908
L44: 1 | M44: =L44+1 -> 2 | N44: =M44+1 -> 3 | O44: =N44+1 -> 4 | P44: =O44+1 -> 5
A45: x | B45: DCF (12/31, USD M) | E45: =E35 -> 2019 | F45: =E45+1 -> 2020 | G45: =F45+1 -> 2021 | H45: =G45+1 -> 2022 | I45: =H45+1 -> 2023 | J45: =I45+1 -> 2024 | K45: =J45+1 -> 2025 | L45: =K45+1 -> 2026 | M45: =L45+1 -> 2027 | ... P45: =O45+1 -> 2030
B46: Revenue | E46: =E26 -> 161857 | F46: =F26 -> 182527 | G46: =G26 -> 257637 | H46: =H26 -> 282836 | I46: =I26 -> 307394 | J46: =J26 -> 350018 | K46: =K26 -> 400240 | L46: =K46*(1+L47) -> 454478.35 | M46: =L46*(1+M47) -> 511371.79 | N46: =M46*(1+N47) -> 568985.83 | O46: =N46*(1+O47) -> 626680.47 | P46: =O46*(1+P47) -> 683870.82
B47: % growth | F47: =F27 -> 0.12770532 | G47: =G27 -> 0.41150076 | H47: =H27 -> 0.097808156 | I47: =I27 -> 0.086827702 | J47: =J27 -> 0.13866243 | K47: =K27 -> 0.14348405 | L47: =OFFSET(L47,$E$12,0) -> 0.13551457 | M47: =OFFSET(M47,$E$12,0) -> 0.12518406 | N47: =OFFSET(N47,$E$12,0) -> 0.11266565 | O47: =OFFSET(O47,$E$12,0) -> 0.10139909 | P47: =OFFSET(P47,$E$12,0) -> 0.091259177
B48: Conservative | L48: =L49*$J$12 -> 0.13551457 | M48: =M49*$J$12 -> 0.12518406 | N48: =M48*(1+$J$13) -> 0.11266565 | O48: =N48*(1+$J$13) -> 0.10139909 | P48: =O48*(1+$J$13) -> 0.091259177
B49: Base (Street) | L49: =L27 -> 0.14264691 | M49: =M27 -> 0.13177269 | N49: =M49*(1+$O$13) -> 0.12188974 | O49: =N49*(1+$O$13) -> 0.11274801 | P49: =O49*(1+$O$13) -> 0.10429191
B50: Optimistic | L50: =L49*$T$12 -> 0.14977926 | M50: =M49*$T$12 -> 0.13836133 | N50: =M50*(1+T13) -> 0.13144326 | O50: =N50*(1+U13) -> 0.13144326 | P50: =O50*(1+V13) -> 0.13144326
B52: EBIT | E52: =E29 -> 34231 | F52: =F29 -> 41224 | G52: =G29 -> 78714 | H52: =H29 -> 74842 | I52: =I29 -> 84293 | J52: =J29 -> 112390 | K52: =K29 -> 130555 | L52: =L53*L46 -> 152796.26 | M52: =M53*M46 -> 177019.05 | N52: =N53*N46 -> 199586.98 | O52: =O53*O46 -> 224159.96 | P52: =P53*P46 -> 246193.49
B53: % of sales | E53: =E30 -> 0.21148915 | F53: =F30 -> 0.22585152 | G53: =G30 -> 0.30552289 | H53: =H30 -> 0.26461271 | I53: =I30 -> 0.2742181 | J53: =J30 -> 0.32109777 | K53: =K30 -> 0.32619178 | L53: =OFFSET(L54,$E$13,0) -> 0.33620141 | M53: =OFFSET(M54,$E$13,0) -> 0.34616507 | N53: =OFFSET(N54,$E$13,0) -> 0.35077671 | O53: =OFFSET(O54,$E$13,0) -> 0.35769418 | P53: =OFFSET(P54,$E$13,0) -> 0.36
...

Sheet WACC
B2: WACC
B4: WACC = % of equity x cost of equity + % of debt x cost of debt x (1 - Tax Rate)
B5: Cost of equity = Risk free rate + Beta x Market Risk Premium
A7: X | B7: WACC
B8: Market Cap | F8: 3990248.3
B9: % of Equity | F9: =F8/F20 -> 0.99461421
B10: Cost of Equity | F10: =F11+F12*F13 -> 0.08619
B11: Risk Free Rate | F11: 0.0423
B12: Beta | F12: 1.05
B13: Market Risk Premium | F13: 0.0418
B15: Debt | F15: 21607
B16: % of Debt | F16: =F15/F20 -> 0.0053857875
B17: Cost of Debt | F17: =(0.0269+0.0544)/2 -> 0.04065
B18: Tax Rate | F18: =DCF!K59 -> 0.15744103
B20: Total | F20: =F15+F8 -> 4011855.3
A22: X | B22: WACC | F22: =(F9*F10)+(F16*F17*(1-F18)) -> 0.085910262

Sheet Shares
B2: Diluted Share Count Calculation
A4: x | B4: Full Diluted Shares
B6: Current price | E6: 327.93
B7: Basic shares outstanding (latest filing) | E7: =5818+842+5407 -> 12067
B8: In-the-money exercisable options | E8: =E32 -> 0
B9: Total proceeds ($mm) | E9: =SUMPRODUCT(D21:D30,E21:E30) -> 0
B10: Total shares repurchased (mm) | E10: =E9/E6 -> 0
B11: Net dilutive options | E11: =E8-E10 -> 0
B13: RSUs | E13: 323
B14: PSUs
B16: Net diluted shares outstanding | E16: =E7+E11+E13+E14 -> 12390
A18: x | B18: Options outstanding
C20: Outstanding | D20: Exercise price | E20: Dilutive Shares
B21: 1 | E21: =IF(D21<$E$6,C21) -> 0
B22: =B21+1 -> 2 | E22: =IF(D22<$E$6,C22) -> 0
B23: =B22+1 -> 3 | E23: =IF(D23<$E$6,C23) -> 0
B24: =B23+1 -> 4 | E24: =IF(D24<$E$6,C24) -> 0
B25: =B24+1 -> 5 | E25: =IF(D25<$E$6,C25) -> 0
B26: =B25+1 -> 6 | E26: =IF(D26<$E$6,C26) -> 0
B27: =B26+1 -> 7 | E27: =IF(D27<$E$6,C27) -> 0
B28: =B27+1 -> 8 | E28: =IF(D28<$E$6,C28) -> 0
B29: =B28+1 -> 9 | E29: =IF(D29<$E$6,C29) -> 0
B30: =B29+1 -> 10 | E30: =IF(D30<$E$6,C30) -> 0
A32: x | B32: Total | E32: =SUM(E21:E30) -> 0

Sheet IS - Historical
A1: Alphabet Inc. Class A (GOOGL)
A2: $327.93
A5: Alphabet Inc. Class A
A6: GOOGL 02079K305 BYVY8G0 NASDAQ Common stock
A7: FactSet Fundamentals
B8: 31 DEC '15 | C8: 31 DEC '16 | D8: 31 DEC '17 | E8: 31 DEC '18 | F8: 31 DEC '19 | G8: 31 DEC '20 | H8: 31 DEC '21 | I8: 31 DEC '22 | J8: 31 DEC '23 | K8: 31 DEC '24
B9: PRELIM
A10: Revenues | B10: 74989 | C10: 90272 | D10: 110855 | E10: 136819 | F10: 161857 | G10: 182527 | H10: 257637 | I10: 282836 | J10: 307394 | K10: 350018
A11: Google (advertising and other) | B11: - | C11: - | D11: - | E11: - | F11: - | G11: - | H11: - | I11: - | J11: - | K11: -
A12: Motorola Mobile (hardware and other) | B12: - | C12: - | D12: - | E12: - | F12: - | G12: - | H12: - | I12: - | J12: - | K12: -
A13: Total costs and expenses | B13: -55629 | C13: -66556 | D13: -84709 | E13: -110498 | F13: -127626 | G13: -141303 | H13: -178923 | I13: -207994 | J13: -223101 | K13: -237628
A14: Cost of revenues | B14: -28164 | C14: -35138 | D14: -45583 | E14: -59549 | F14: -71896 | G14: -84732 | H14: -110939 | I14: -126203 | J14: -133332 | K14: -146306
A15: Cost of revenues - Motorola Mobile (hardware and other) | B15: - | C15: - | D15: - | E15: - | F15: - | G15: - | H15: - | I15: - | J15: - | K15: -
A16: Research and development | B16: -12282 | C16: -13948 | D16: -16625 | E16: -21419 | F16: -26018 | G16: -27573 | H16: -31562 | I16: -39500 | J16: -45427 | K16: -49326
A17: Sales and marketing | B17: -9047 | C17: -10485 | D17: -12893 | E17: -16333 | F17: -18464 | G17: -17946 | H17: -22912 | I17: -26567 | J17: -27917 | K17: -27808
A18: General and administrative | B18: -6136 | C18: -6985 | D18: -6872 | E18: -8126 | F18: -9551 | G18: -11052 | H18: -13510 | I18: -15724 | J18: -16425 | K18: -14188
A19: European commission fine | B19: - | C19: - | D19: -2736 | E19: -5071 | F19: -1697 | G19: 0 | H19: 0 | I19: - | J19: - | K19: -
A20: Contribution to Google Foundation | B20: - | C20: - | D20: - | E20: - | F20: - | G20: - | H20: - | I20: - | J20: - | K20: -
A21: Non-recurring portion of settlement of disputes with Yahoo | B21: - | C21: - | D21: - | E21: - | F21: - | G21: - | H21: - | I21: - | J21: - | K21: -
A22: Charge related to the resolution of Department of Justice Investigation | B22: - | C22: - | D22: - | E22: - | F22: - | G22: - | H22: - | I22: - | J22: - | K22: -
A23: Income from operations | B23: 19360 | C23: 23716 | D23: 26146 | E23: 26321 | F23: 34231 | G23: 41224 | H23: 78714 | I23: 74842 | J23: 84293 | K23: 112390
A24: Impairment of equity investments | B24: - | C24: - | D24: - | E24: - | F24: - | G24: - | H24: - | I24: - | J24: - | K24: -
A25: Other income / expense, net | B25: 291 | C25: 434 | D25: 1047 | E25: 8592 | F25: 5394 | G25: 6858 | H25: 12020 | I25: -3514 | J25: 1424 | K25: 7425
A26: Income before income taxes | B26: 19651 | C26: 24150 | D26: 27193 | E26: 34913 | F26: 39625 | G26: 48082 | H26: 90734 | I26: 71328 | J26: 85717 | K26: 119815
A27: Provision for income taxes | B27: -3303 | C27: -4672 | D27: -14531 | E27: -4177 | F27: -5282 | G27: -7813 | H27: -14701 | I27: -11356 | J27: -11922 | K27: -19697
A28: Net income from continuing operations | B28: 16348 | C28: 19478 | D28: 12662 | E28: 30736 | F28: 34343 | G28: 40269 | H28: 76033 | I28: 59972 | J28: 73795 | K28: 100118
A29: Net income / loss from discontinued operations | B29: 0 | C29: 0 | D29: - | E29: - | F29: - | G29: - | H29: - | I29: - | J29: - | K29: -
A30: Net income / loss | B30: 16348 | C30: 19478 | D30: 12662 | E30: 30736 | F30: 34343 | G30: 40269 | H30: 76033 | I30: 59972 | J30: 73795 | K30: 100118
A31: Adjustment payment to Class C capital stockholders | B31: -522 | C31: 0 | D31: 0 | E31: - | F31: - | G31: - | H31: - | I31: - | J31: - | K31: -
A32: Net income available to all stockholders | B32: 15826 | C32: 19478 | D32: 12662 | E32: 30736 | F32: 34343 | G32: 40269 | H32: 76033 | I32: 59972 | J32: 73795 | K32: 100118
A33: Per share
A34: Class A and B common stock and Class C capital stock
A35: Basic | B35: 1.1555 | C35: 1.416 | D35: 0.9135 | E35: 44.22 | F35: 49.59 | G35: 59.15 | H35: 113.88 | I35: 4.59 | J35: 5.84 | K35: 8.13
A36: Continuing operations | B36: 1.1555 | C36: 1.416 | D36: 0.9135 | E36: - | F36: - | G36: - | H36: - | I36: - | J36: - | K36: -
A37: Discontinued operations | B37: 0 | C37: 0 | D37: 0 | E37: - | F37: - | G37: - | H37: - | I37: - | J37: - | K37: -
A38: Diluted | B38: 1.142 | C38: 1.3925 | D38: 0.9 | E38: 43.7 | F38: 49.16 | G38: 58.61 | H38: 112.2 | I38: 4.56 | J38: 5.8 | K38: 8.04
A39: Continuing operations | B39: 1.142 | C39: 1.3925 | D39: 0.9 | E39: - | F39: - | G39: - | H39: - | I39: - | J39: - | K39: -
A40: Discontinued operations | B40: 0 | C40: 0 | D40: 0 | E40: - | F40: - | G40: - | H40: - | I40: - | J40: - | K40: -
A41: Class A
A42: Basic | B42: - | C42: - | D42: - | E42: - | F42: - | G42: - | H42: - | I42: - | J42: - | K42: -
...

Sheet CFS - Historicals
A1: Alphabet Inc. Class A (GOOGL)
A2: $327.93
A5: Alphabet Inc. Class A
A6: GOOGL 02079K305 BYVY8G0 NASDAQ Common stock
A7: FactSet Fundamentals
B8: 31 DEC '15 | C8: 31 DEC '16 | D8: 31 DEC '17 | E8: 31 DEC '18 | F8: 31 DEC '19 | G8: 31 DEC '20 | H8: 31 DEC '21 | I8: 31 DEC '22 | J8: 31 DEC '23 | K8: 31 DEC '24
B9: PRELIM
A10: Net cash provided by operating activities | B10: 26024 | C10: 36036 | D10: 37091 | E10: 47971 | F10: 54520 | G10: 65124 | H10: 91652 | I10: 91495 | J10: 101746 | K10: 125299
A11: Net income | B11: 16348 | C11: 19478 | D11: 12662 | E11: 30736 | F11: 34343 | G11: 40269 | H11: 76033 | I11: 59972 | J11: 73795 | K11: 100118
A12: Adjustments | B12: 9676 | C12: 16558 | D12: 24429 | E12: 17235 | F12: 20177 | G12: 24855 | H12: 15619 | I12: 31523 | J12: 27951 | K12: 25181
A13: Depreciation and impairment of property and equipment | B13: 4132 | C13: 5267 | D13: 6103 | E13: 8164 | F13: 10856 | G13: 12905 | H13: 11555 | I13: 15287 | J13: 11946 | K13: 15311
A14: Amortization and impairment of intangible assets | B14: 931 | C14: 877 | D14: 812 | E14: 871 | F14: 925 | G14: 792 | H14: 886 | I14: 641 | J14: - | K14: -
A15: Stock-based compensation expense | B15: 5203 | C15: 6703 | D15: 7679 | E15: 9353 | F15: 10794 | G15: 12991 | H15: 15376 | I15: 19362 | J15: 22460 | K15: 22785
A16: Excess tax benefits from stock-based award activities | B16: -548 | C16: - | D16: - | E16: - | F16: - | G16: - | H16: - | I16: - | J16: - | K16: -
A17: Non-recurring portion of settlement of disputes with Yahoo | B17: - | C17: - | D17: - | E17: - | F17: - | G17: - | H17: - | I17: - | J17: - | K17: -
A18: Deferred income taxes | B18: -179 | C18: -38 | D18: 258 | E18: 778 | F18: 173 | G18: 1390 | H18: 1808 | I18: -8081 | J18: -7763 | K18: -5257
A19: Gain / loss on debt and equity securities, net | B19: - | C19: - | D19: - | E19: -6650 | F19: -2798 | G19: -6317 | H19: -12270 | I19: 5519 | J19: 823 | K19: -2671
A20: Impairment of equity investments | B20: - | C20: - | D20: - | E20: - | F20: - | G20: - | H20: - | I20: - | J20: - | K20: -
A21: Gain / loss on divestiture of business | B21: 0 | C21: 0 | D21: - | E21: - | F21: - | G21: - | H21: - | I21: - | J21: - | K21: -
A22: Gain on equity interest | B22: - | C22: - | D22: - | E22: - | F22: - | G22: - | H22: - | I22: - | J22: - | K22: -
A23: Other | B23: 546 | C23: 449 | D23: 331 | E23: -189 | F23: -592 | G23: 1267 | H23: -213 | I23: 1030 | J23: 4330 | K23: 3419
A24: In-process research and development | B24: - | C24: - | D24: - | E24: - | F24: - | G24: - | H24: - | I24: - | J24: - | K24: -
A25: Gain on sale of marketable equity securities | B25: 334 | C25: 275 | D25: 194 | E25: - | F25: - | G25: - | H25: - | I25: - | J25: - | K25: -
A26: Other excluding in-process research and development and gain on sale of marketable equity securities | B26: 212 | C26: 174 | D26: 137 | E26: - | F26: - | G26: - | H26: - | I26: - | J26: - | K26: -
A27: Changes in assets and liabilities, net of effects of acquisitions | B27: -409 | C27: 3300 | D27: 9246 | E27: 4908 | F27: 819 | G27: 1827 | H27: -1523 | I27: -2235 | J27: -3845 | K27: -8406
A28: Accounts receivable | B28: -2094 | C28: -2578 | D28: -3768 | E28: -2169 | F28: -4340 | G28: -6524 | H28: -9095 | I28: -2317 | J28: -7833 | K28: -5891
A29: Income taxes, net | B29: -179 | C29: 3125 | D29: 8211 | E29: -2251 | F29: -3128 | G29: 1209 | H29: -625 | I29: 584 | J29: 523 | K29: -2418
A30: Prepaid revenue share, expenses and other assets | B30: -318 | C30: 312 | D30: -2164 | E30: -1207 | F30: -621 | G30: -1330 | H30: -1846 | I30: -5046 | J30: -2143 | K30: -1397
A31: Inventories | B31: - | C31: - | D31: - | E31: - | F31: - | G31: - | H31: - | I31: - | J31: - | K31: -
A32: Prepaid revenue share, expenses and other assets excluding inventories | B32: - | C32: - | D32: - | E32: - | F32: - | G32: - | H32: - | I32: - | J32: - | K32: -
A33: Accounts payable | B33: 203 | C33: 110 | D33: 731 | E33: 1067 | F33: 428 | G33: 694 | H33: 283 | I33: 707 | J33: 664 | K33: 359
A34: Accrued expenses and other liabilities | B34: 1597 | C34: 1515 | D34: 4891 | E34: 8614 | F34: 7170 | G34: 5504 | H34: 7304 | I34: 3915 | J34: 3937 | K34: -1161
A35: Accrued revenue share | B35: 339 | C35: 593 | D35: 955 | E35: 483 | F35: 1273 | G35: 1639 | H35: 1682 | I35: -445 | J35: 482 | K35: 1059
A36: Deferred revenue | B36: 43 | C36: 223 | D36: 390 | E36: 371 | F36: 37 | G36: 635 | H36: 774 | I36: 367 | J36: 525 | K36: 1043
A37: Net cash used in / provided by investing activities | B37: -23711 | C37: -31165 | D37: -31401 | E37: -28504 | F37: -29491 | G37: -32773 | H37: -35523 | I37: -20298 | J37: -27063 | K37: -45536
A38: Purchases of property and equipment | B38: -9915 | C38: -9972 | D38: -13085 | E38: -25041 | F38: -22959 | G38: -22213 | H38: -24099 | I38: -29896 | J38: -33302 | K38: -55202
A39: Purchases of property and equipment excluding proceeds from disposals of property and equipment | B39: - | C39: -10212 | D39: -13184 | E39: -25139 | F39: -23548 | G39: -22281 | H39: -24640 | I39: -31485 | J39: -32251 | K39: -52535
A40: Proceeds from disposals of property and equipment | B40: - | C40: 240 | D40: 99 | E40: 98 | F40: 589 | G40: 68 | H40: 541 | I40: 1589 | J40: -1051 | K40: -2667
A41: Purchases of marketable securities | B41: -74368 | C41: -84509 | D41: -92195 | E41: -50158 | F41: -100315 | G41: -136576 | H41: -135196 | I41: -78874 | J41: -77858 | K41: -86679
A42: Maturities and sales of marketable securities | B42: 62905 | C42: 66895 | D42: 73959 | E42: 48507 | F42: 97825 | G42: 132906 | H42: 128294 | I42: 97822 | J42: 86672 | K42: 103428
...

Sheet IS - Estimates
A1: GOOGL-US
A2: Income Statement (M)
B3: CY '19 | C3: CY '20 | D3: CY '21 | E3: CY '22 | F3: CY '23 | G3: CY '24 | H3: CY '25E | I3: CY '26E | J3: CY '27E | K3: CY '28E | L3: CY '29E | M3: CY '30E
B4: Dec '19 | C4: Dec '20 | D4: Dec '21 | E4: Dec '22 | F4: Dec '23 | G4: Dec '24 | H4: Dec '25E | I4: Dec '26E | J4: Dec '27E | K4: Dec '28E | L4: Dec '29E | M4: Dec '30E
A5: Sales | B5: 161857 | C5: 182527 | D5: 257637 | E5: 282836 | F5: 307394 | G5: 350018 | H5: 400240 | I5: 457333 | J5: 517597 | K5: 583105 | L5: 643579 | M5: 714542
A6: Cost of Sales | B6: 71896 | C6: 84732 | D6: 110939 | E6: 126203 | F6: 133332 | G6: 146306 | H6: 162390 | I6: 172527 | J6: 194597 | K6: 224924 | L6: 238254 | M6: 264236
A7: Gross Income | B7: 89961 | C7: 97795 | D7: 146698 | E7: 156633 | F7: 174062 | G7: 203712 | H7: 238024 | I7: 272392 | J7: 308217 | K7: 343066 | L7: 385257 | M7: 427598
A8: EBITDA | B8: 58682.8 | C8: 67912 | D8: 106531 | E8: 110132 | F8: 120582 | G8: 150486 | H8: 177367 | I8: 213548 | J8: 250279 | K8: 292557 | L8: 340523 | M8: 391214
A9: Operating Income | B9: 34231 | C9: 41224 | D9: 78714 | E9: 74842 | F9: 84293 | G9: 112390 | H9: 130555 | I9: 153756 | J9: 179174 | K9: 204405 | L9: 232058 | M9: 261313
A10: Interest Income | B10: - | C10: - | D10: - | E10: - | F10: - | G10: - | H10: 3959.53 | I10: 4026.4 | J10: 4870 | K10: 5275 | L10: 3278 | M10: 3352
A11: Pretax Income | B11: 39625 | C11: 48082 | D11: 90734 | E11: 71328 | F11: 85717 | G11: 119815 | H11: 157789 | I11: 162605 | J11: 186520 | K11: 211842 | L11: 247422 | M11: 282905
A12: Tax Expense | B12: 5282 | C12: 7813 | D12: 14701 | E12: 11356 | F12: 11922 | G12: 19697 | H12: 28063.9 | I12: 25777.4 | J12: 29825.2 | K12: 35818.3 | L12: 33688 | M12: 36759
A13: Net Income | B13: 34343 | C13: 40269 | D13: 76033 | E13: 59972 | F13: 73795 | G13: 100118 | H13: 129603 | I13: 135876 | J13: 155743 | K13: 176165 | L13: 203545 | M13: 231845

Sheet CFS - Estimates
A1: GOOGL-US
A2: Cash Flow (M)
B3: CY '19 | C3: CY '20 | D3: CY '21 | E3: CY '22 | F3: CY '23 | G3: CY '24 | H3: CY '25E | I3: CY '26E | J3: CY '27E | K3: CY '28E | L3: CY '29E | M3: CY '30E
B4: Dec '19 | C4: Dec '20 | D4: Dec '21 | E4: Dec '22 | F4: Dec '23 | G4: Dec '24 | H4: Dec '25E | I4: Dec '26E | J4: Dec '27E | K4: Dec '28E | L4: Dec '29E | M4: Dec '30E
A5: Capital Expenditures | B5: 23548 | C5: 22281 | D5: 24640 | E5: 31485 | F5: 32251 | G5: 52535 | H5: 89125.8 | I5: 115437 | J5: 131411 | K5: 137222 | L5: 140447 | M5: 149738
A6: Free Cash Flow | B6: 30972 | C6: 42843 | D6: 67012 | E6: 60010 | F6: 69495 | G6: 72764 | H6: 65169.1 | I6: 69222.6 | J6: 97273.2 | K6: 122873 | L6: 180735 | M6: 212748
A7: Deferred Income Taxes (CF) | B7: - | C7: - | D7: 1808 | E7: - | F7: - | G7: - | H7: - | I7: - | J7: - | K7: - | L7: - | M7: -
A8: Cash Flow from Operations | B8: 54520 | C8: 65124 | D8: 91652 | E8: 91495 | F8: 101746 | G8: 125299 | H8: 157946 | I8: 188219 | J8: 224314 | K8: 274315 | L8: 322902 | M8: 370016
A9: Cash Flow from Investing | B9: -29491 | C9: -32773 | D9: -35523 | E9: -20298 | F9: -27063 | G9: -45536 | H9: -90226.6 | I9: -111287 | J9: -120243 | K9: -139966 | L9: -146140 | M9: -152693
A10: Cash Flow from Financing | B10: -23209 | C10: -24408 | D10: -61362 | E10: -69757 | F10: -72093 | G10: -79733 | H10: -60165.4 | I10: -64432.1 | J10: -77179.5 | K10: -89971 | L10: -112023 | M10: -134761
A12: D&A | H12: 21703 | I12: 30959.5 | J12: 42393.9 | K12: 58174.5 | L12: 74564.1 | M12: 91638.4
