Workbook
Name D: WACC!$D$15
Name D_perc: WACC!$D$17
Name E: WACC!$D$14
Name E_perc: WACC!$D$16
Name kd: WACC!$D$19
Name ke: WACC!$D$12
Name Tax_shield: WACC!$D$18

Sheet DCF
C3: DCF Model
A6: • | C6: Overview
C8: Comp Name | E8: McDonald's Corporation | G8: Valuation | I8: =R104*I11 -> 318.93484
C9: Ticker | E9: MCD | G9: %Delta vs Current | I9: =I8/E11-1 -> 0.027330778
C10: Date | E10: =TODAY() -> 46160
C11: Price per Share | E11: 310.45 | G11: Exch. EUR-USD | I11: 1.18
C15: Assumptions
C17: Triggers | G17: Conservative | J17: Year | K17: Amount | M17: Base/ Street | O17: Year | P17: Amount | R17: Optimistic | T17: Year | U17: Amount
C18: Scenario | E18: 1 | G18: Revenue growth | J18: 25-'30 | K18: -0.2 | R18: Revenue Growth | T18: 25-'30 | U18: 0.55
C19: WACC | E19: 0.0613 | G19: EBIDTA Margin | J19: 25 | K19: -0.05 | R19: EBIDTA Margin | T19: 25 | U19: 0
C20: TGR | E20: 0.025 | G20: EBITDA Margin | J20: 30 | K20: -0.15 | R20: EBITDA Margin | T20: 30 | U20: 0.05
G21: D&A | J21: 25 | K21: 0 | R21: D&A | T21: 25-'30 | U21: 0
G22: WACC | K22: 0.062 | M22: WACC | P22: 0.0613 | R22: WACC | U22: 0.06
G23: TGR | K23: 0.022 | M23: TGR | P23: 0.025 | R23: TGR | U23: 0.028
A26: • | C26: Income Statement
H28: Actuals | M28: Projections
C29: $M | H29: 2020 | I29: =H29+1 -> 2021 | J29: =I29+1 -> 2022 | K29: =J29+1 -> 2023 | L29: =K29+1 -> 2024 | M29: =L29+1 -> 2025 | N29: =M29+1 -> 2026 | O29: =N29+1 -> 2027 | P29: =O29+1 -> 2028 | ... R29: =Q29+1 -> 2030
C30: Revenue | H30: =IS!H11 -> 16849 | I30: =IS!I11 -> 19647 | J30: =IS!J11 -> 22058 | K30: =IS!K11 -> 23581 | L30: =IS!L11 -> 23962 | M30: =L30*(1+M31) -> 24561.05 | N30: =M30*(1+N31) -> 25175.076 | O30: =N30*(1+O31) -> 25804.453 | P30: =O30*(1+P31) -> 26449.564 | Q30: =P30*(1+Q31) -> 27110.804 | R30: =Q30*(1+R31) -> 27788.574
C31: % growth | I31: =I30/H30-1 -> 0.16606327 | J31: =J30/I30-1 -> 0.12271594 | K31: =K30/J30-1 -> 0.069045244 | L31: =L30/K30-1 -> 0.016157076 | M31: =OFFSET(M31,E18,0) -> 0.025 | N31: =OFFSET(N31,$E$18,0) -> 0.025 | O31: =OFFSET(O31,$E$18,0) -> 0.025 | P31: =OFFSET(P31,$E$18,0) -> 0.025 | Q31: =OFFSET(Q31,$E$18,0) -> 0.025 | R31: =OFFSET(R31,$E$18,0) -> 0.025
C32: 1. Base | M32: 0.025 | N32: =M32 -> 0.025 | O32: =N32 -> 0.025 | P32: =O32 -> 0.025 | Q32: =P32 -> 0.025 | R32: =Q32 -> 0.025
C33: 2. Conservative | M33: =M32*(1+K18) -> 0.02 | N33: =M33 -> 0.02 | O33: =N33 -> 0.02 | P33: =O33 -> 0.02 | Q33: =P33 -> 0.02 | R33: =Q33 -> 0.02
C34: 3. Optimistic | M34: =M32*(1+U18) -> 0.03875 | N34: =M34 -> 0.03875 | O34: =N34 -> 0.03875 | P34: =O34 -> 0.03875 | Q34: =P34 -> 0.03875 | R34: =Q34 -> 0.03875
C36: COGS | H36: =IS!H13*-1 -> -6788 | I36: =-IS!I13 -> -7482 | J36: =-IS!J13 -> -7831 | K36: =-IS!K13 -> -8419 | L36: =-IS!L13 -> -8525 | M36: =M38-M30 -> -8524.4558 | N36: =N38-N30 -> -8507.4421 | O36: =O38-O30 -> -8480.9476 | P36: =P38-P30 -> -8692.9712 | Q36: =Q38-Q30 -> -8910.2955 | R36: =R38-R30 -> -9133.0529
C38: Gross profit | H38: =H30+H36 -> 10061 | I38: =I30+I36 -> 12165 | J38: =J30+J36 -> 14227 | K38: =K30+K36 -> 15162 | L38: =L30+L36 -> 15437 | M38: =M30*M39 -> 16036.594 | N38: =N30*N39 -> 16667.634 | O38: =O30*O39 -> 17323.506 | P38: =P30*P39 -> 17756.593 | Q38: =Q30*Q39 -> 18200.508 | R38: =R30*R39 -> 18655.521
C39: % margin | H39: =H38/H30 -> 0.59712743 | I39: =I38/I30 -> 0.6191785 | J39: =J38/J30 -> 0.64498141 | K39: =K38/K30 -> 0.64297528 | L39: =L38/L30 -> 0.64422836 | M39: =L39*(1+M40) -> 0.65292788 | N39: =M39*(1+N40) -> 0.66206887 | O39: =N39*(1+O40) -> 0.67133783 | P39: =O39*(1+P40) -> 0.67133783 | Q39: =P39*(1+Q40) -> 0.67133783 | R39: =Q39*(1+R40) -> 0.67133783
C40: % growth | I40: =I39/H39-1 -> 0.036928591 | J40: =J39/I39-1 -> 0.041672817 | K40: =K39/J39-1 -> -0.0031103779 | L40: =L39/K39-1 -> 0.001948885 | M40: =OFFSET(M40,$E$18,0) -> 0.013503775 | N40: =OFFSET(N40,$E$18,0) -> 0.014 | O40: =OFFSET(O40,$E$18,0) -> 0.014 | P40: =OFFSET(P40,$E$18,0) -> 0 | Q40: =OFFSET(Q40,$E$18,0) -> 0 | R40: =OFFSET(R40,$E$18,0) -> 0
C41: 1. Base | M41: =AVERAGE(J40:L40) -> 0.013503775 | N41: 0.014 | O41: =N41 -> 0.014 | P41: 0 | Q41: =P41 -> 0 | R41: =Q41 -> 0
C42: 2. Conservative | M42: =AVERAGE(K40:L40) -> -0.00058074646 | N42: =AVERAGE(K40:L40) -> -0.00058074646 | O42: =N42 -> -0.00058074646 | P42: =O42 -> -0.00058074646 | Q42: =P42 -> -0.00058074646 | R42: =Q42 -> -0.00058074646
C43: 3. Optimistic | M43: 0.03 | N43: 0.03 | O43: =N43 -> 0.03 | P43: =O43 -> 0.03 | Q43: =P43 -> 0.03 | R43: =Q43 -> 0.03
C45: Opex | H45: =IS!H18*-1 -> -2243 | I45: =IS!I18*-1 -> -2316 | J45: =IS!J18*-1 -> -2595 | K45: =IS!K18*-1 -> -2492 | L45: =IS!L18*-1 -> -2535 | M45: =M48-M38 -> -2528.0167 | N45: =N48-N38 -> -2821.3423 | O45: =O48-O38 -> -2873.0118 | P45: =P48-P38 -> -2944.8371 | Q45: =Q48-Q38 -> -2476.242 | R45: =R48-R38 -> -2538.148
C46: % sales | H46: =H45/H30*-1 -> 0.13312363 | I46: =I45/I30*-1 -> 0.11788059 | J46: =J45/J30*-1 -> 0.11764439 | K46: =K45/K30*-1 -> 0.1056783 | L46: =L45/L30*-1 -> 0.1057925 | M46: =M45/M30*-1 -> 0.10292788 | N46: =N45/N30*-1 -> 0.11206887 | O46: =O45/O30*-1 -> 0.11133783 | ... R46: =R45/R30*-1 -> 0.091337831
C48: EBITDA | H48: =H38+H45 -> 7818 | I48: =I38+I45 -> 9849 | J48: =J38+J45 -> 11632 | K48: =K38+K45 -> 12670 | L48: =L38+L45 -> 12902 | M48: =M30*M49 -> 13508.578 | N48: =N30*N49 -> 13846.292 | O48: =O30*O49 -> 14450.494 | P48: =P30*P49 -> 14811.756 | Q48: =Q30*Q49 -> 15724.266 | R48: =R30*R49 -> 16117.373
C49: % margin | H49: =H48/H30 -> 0.4640038 | I49: =I48/I30 -> 0.50129791 | J49: =J48/J30 -> 0.52733702 | K49: =K48/K30 -> 0.53729698 | L49: =L48/L30 -> 0.53843586 | M49: =OFFSET(M49,$E$18,0) -> 0.55 | N49: =OFFSET(N49,$E$18,0) -> 0.55 | O49: =OFFSET(O49,$E$18,0) -> 0.56 | P49: =OFFSET(P49,$E$18,0) -> 0.56 | Q49: =OFFSET(Q49,$E$18,0) -> 0.58 | R49: =OFFSET(R49,$E$18,0) -> 0.58
C50: 1. Base | M50: 0.55 | N50: 0.55 | O50: 0.56 | P50: 0.56 | Q50: 0.58 | R50: 0.58
C51: 2. Conservative | M51: =M50*(1+K19) -> 0.5225 | N51: =N50*(1+K19) -> 0.5225 | O51: =N51 -> 0.5225 | P51: =O51 -> 0.5225 | Q51: =P51 -> 0.5225 | R51: =Q51 -> 0.5225
C52: 3. Optimistic | M52: =M50*(1+U19) -> 0.55 | N52: =N50*(1+U19) -> 0.55 | O52: =N52+(($R$52-$N$52)/($R$29-$N$29)) -> 0.565 | P52: =O52+(($R$52-$N$52)/($R$29-$N$29)) -> 0.58 | Q52: =P52+(($R$52-$N$52)/($R$29-$N$29)) -> 0.595 | R52: 0.61
C54: D&A | H54: =IS!H14*-1 -> -1536 | I54: =IS!I14*-1 -> -1580 | J54: =IS!J14*-1 -> -1780 | K54: =IS!K14*-1 -> -1830 | L54: =IS!L14*-1 -> -1939 | M54: =M30*M56*-1 -> -2005.5706 | N54: =N30*N56*-1 -> -2029.8478 | O54: =O30*O56*-1 -> -2103.827 | P54: =P30*P56*-1 -> -2051.1496 | Q54: =Q30*Q56*-1 -> -1800.6914 | R54: =R30*R56*-1 -> -1770.1186
C55: % sales | H55: =H54/H30*-1 -> 0.09116268 | I55: =I54/I30*-1 -> 0.080419402 | J55: =J54/J30*-1 -> 0.080696346 | K55: =K54/K30*-1 -> 0.077604851 | L55: =L54/L30*-1 -> 0.08091979 | M55: =OFFSET(M55,$E$18,0) -> 0.081656548 | N55: =OFFSET(N55,$E$18,0) -> 0.080629261 | O55: =OFFSET(O55,$E$18,0) -> 0.08152961 | P55: =OFFSET(P55,$E$18,0) -> 0.077549467 | Q55: =OFFSET(Q55,$E$18,0) -> 0.066419698 | R55: =OFFSET(R55,$E$18,0) -> 0.063699513
C56: 1. Base | M56: ='Estimates IS'!H17 -> 0.081656548 | N56: ='Estimates IS'!I17 -> 0.080629261 | O56: ='Estimates IS'!J17 -> 0.08152961 | P56: ='Estimates IS'!K17 -> 0.077549467 | Q56: ='Estimates IS'!L17 -> 0.066419698 | R56: ='Estimates IS'!M17 -> 0.063699513
C57: 2. Conservative | M57: =M56*(1+K21) -> 0.081656548 | N57: =N56*(1+L21) -> 0.080629261 | O57: =O56*(1+M21) -> 0.08152961 | P57: =P56*(1+N21) -> 0.077549467 | Q57: =Q56*(1+O21) -> 0.066419698 | R57: =R56*(1+P21) -> 0.063699513
...

Sheet Summary
B3: Summary
A6: • | C6: Valuation
C8: Metrics | D8: DCF | E8: EV / Revenue | F8: EV / EBITDA | G8: P / Sales | H8: P / E | I8: 52-wk Range
C9: Mean | D9: 319 | E9: =Comps!R32 -> 32.283934 | F9: =Comps!S32 -> 308.2308 | G9: =Comps!T32 -> 83.687265 | H9: =Comps!U32 -> 556.36082 | I9: ='52 Week Share Price'!G8 -> 304.5654
C10: Median | E10: =Comps!R33 -> 47.404106 | F10: =Comps!S33 -> 314.6232 | G10: =Comps!T33 -> 101.51726 | H10: =Comps!U33 -> 481.37529 | I10: ='52 Week Share Price'!G9 -> 305.54
C11: 25th percentile | D11: 209 | E11: =Comps!R34 -> -23.458141 | F11: =Comps!S34 -> 226.17726 | G11: =Comps!T34 -> 27.888804 | H11: =Comps!U34 -> 403.00182 | I11: ='52 Week Share Price'!G10 -> 299.455
C12: 75th percentile | D12: 443 | E12: =Comps!R35 -> 80.893225 | F12: =Comps!S35 -> 424.20604 | G12: =Comps!T35 -> 111.50936 | H12: =Comps!U35 -> 491.05315 | I12: ='52 Week Share Price'!G11 -> 311.3975
A14: • | C14: Football Chart
C16: Method | D16: Min | E16: Difference | F16: Max
C17: DCF | D17: =D11 -> 209 | E17: =F17-D17 -> 234 | F17: =D12 -> 443
C18: EV/Revenue | D18: =E11 -> -23.458141 | E18: =F18-D18 -> 104.35137 | F18: =E12 -> 80.893225
C19: EV/EBITDA | D19: =F11 -> 226.17726 | E19: =F19-D19 -> 198.02878 | F19: =F12 -> 424.20604
C20: P/Sales | D20: =G11 -> 27.888804 | E20: =F20-D20 -> 83.620555 | F20: =G12 -> 111.50936
C21: P/E | D21: =H11 -> 403.00182 | E21: =F21-D21 -> 88.051327 | F21: =H12 -> 491.05315
C22: 52-wk Range | D22: =I11 -> 299.455 | E22: =F22-D22 -> 11.9425 | F22: =I12 -> 311.3975

Sheet Comps
A6: • | C6: Comps
C7: all Values in B USD
C9: Name | D9: Employees | E9: Revenue | F9: Rev Growth | G9: EBITDA | H9: EBITDA % | I9: Net Income | J9: NI % | K9: Price/Share | L9: Market Cap | M9: EV | N9: EV/ Revenue | O9: EV/EBITDA | P9: P/Sales | Q9: P/E | R9: Selected?
C10: Mcdonald's | D10: 150000 | E10: 26.27 | F10: 0.0125 | G10: 14.33 | H10: =G10/E10 -> 0.54548915 | I10: 8.41 | J10: =I10/E10 -> 0.32013704 | K10: 302.11 | L10: 216.86 | M10: 270.85
C11: Tyson Foods | D11: 133000 | E11: 54.44 | F11: 0.0212 | G11: 2.51 | H11: =G11/E11 -> 0.046105805 | I11: 0.474 | J11: =I11/E11 -> 0.0087068332 | K11: 56.93 | L11: 19.32 | M11: 26.97 | N11: =M11/E11 -> 0.49540779 | O11: =M11/G11 -> 10.74502 | P11: =L11/E11 -> 0.35488611 | Q11: =L11/I11 -> 40.759494 | R11: X
C12: Starbucks | D12: 381000 | E12: 37.18 | F12: 0.0279 | G12: 4.71 | H12: =G12/E12 -> 0.12668101 | I12: 1.86 | J12: =I12/E12 -> 0.050026896 | K12: 89.15 | L12: 96.16 | M12: 119.55 | N12: =M12/E12 -> 3.2154384 | O12: =M12/G12 -> 25.382166 | P12: =L12/E12 -> 2.5863367 | Q12: =L12/I12 -> 51.698925
C13: Chipotle | D13: 130000 | E13: 11.79 | F13: 0.0731 | G13: 2.28 | H13: =G13/E13 -> 0.19338422 | I13: 1.54 | J13: =I13/E13 -> 0.13061917 | K13: 38.91 | L13: 52.55 | M13: 55.78 | N13: =M13/E13 -> 4.7311281 | O13: =M13/G13 -> 24.464912 | P13: =L13/E13 -> 4.4571671 | Q13: =L13/I13 -> 34.123377 | R13: X
C14: Burger King | D14: 6000
C15: KFC | E15: 33.36
C16: Domino's | D16: 10700 | E16: 4.85 | F16: 0.0392 | G16: 1.03 | H16: =G16/E16 -> 0.21237113 | I16: 0.5 | J16: =I16/E16 -> 0.10309278 | K16: 412.22 | L16: 14.66 | M16: 19.59 | N16: =M16/E16 -> 4.0391753 | O16: =M16/G16 -> 19.019417 | P16: =L16/E16 -> 3.0226804 | Q16: =L16/I16 -> 29.32 | R16: X
C17: Jack In The Box | D17: 5046 | E17: 1.47 | F17: -0.0675 | G17: 0.034 | H17: =G17/E17 -> 0.023129252 | I17: -0.08 | J17: =I17/E17 -> -0.054421769 | K17: 20.42 | L17: 0.373 | M17: 3.47
C18: Papa John's | D18: 11400 | E18: 2.09 | F18: -0.0064 | G18: 0.173 | H18: =G18/E18 -> 0.08277512 | I18: 0.038 | J18: =I18/E18 -> 0.018181818 | K18: 39.95 | L18: 1.58 | M18: 2.53 | N18: =M18/E18 -> 1.2105263 | O18: =M18/G18 -> 14.624277 | P18: =L18/E18 -> 0.75598086 | Q18: =L18/I18 -> 41.578947 | R18: X
C19: Subway
C20: Wendy's | D20: 14500 | E20: 2.21 | F20: -0.0021 | G20: 0.552 | H20: =G20/E20 -> 0.24977376 | I20: 0.186 | J20: =I20/E20 -> 0.084162896 | K20: 8.35 | L20: 1.75 | M20: 5.55 | N20: =M20/E20 -> 2.5113122 | O20: =M20/G20 -> 10.054348 | P20: =L20/E20 -> 0.7918552 | Q20: =L20/I20 -> 9.4086022
C21: Chick-fil-A
C22: Shake Shack | D22: 12826 | E22: 1.37 | F22: 0.1349 | G22: 0.174 | H22: =G22/E22 -> 0.1270073 | I22: 0.042 | J22: =I22/E22 -> 0.030656934 | K22: 89.6 | L22: 3.77 | M22: 4.29 | N22: =M22/E22 -> 3.1313869 | O22: =M22/G22 -> 24.655172 | P22: =L22/E22 -> 2.7518248 | Q22: =L22/I22 -> 89.761905 | R22: X
C23: Mean | D23: {=AVERAGE(IF($R$11:$R$22="X",D11:D22))} -> 59585.2 | E23: {=AVERAGE(IF($R$11:$R$22="X",E11:E22))} -> 14.908 | F23: {=AVERAGE(IF($R$11:$R$22="X",F11:F22))} -> 0.0524 | G23: {=AVERAGE(IF($R$11:$R$22="X",G11:G22))} -> 1.2334 | H23: {=AVERAGE(IF($R$11:$R$22="X",H11:H22))} -> 0.13232872 | I23: {=AVERAGE(IF($R$11:$R$22="X",I11:I22))} -> 0.5188 | J23: {=AVERAGE(IF($R$11:$R$22="X",J11:J22))} -> 0.058251508 | K23: {=AVERAGE(IF($R$11:$R$22="X",K11:K22))} -> 127.522 | ... Q23: {=AVERAGE(IF($R$11:$R$22="X",Q11:Q22))} -> 47.108744
C24: Median | D24: {=MEDIAN(IF($R$11:$R$22="X",D11:D22))} -> 12826 | E24: {=MEDIAN(IF($R$11:$R$22="X",E11:E22))} -> 4.85 | F24: {=MEDIAN(IF($R$11:$R$22="X",F11:F22))} -> 0.0392 | G24: {=MEDIAN(IF($R$11:$R$22="X",G11:G22))} -> 1.03 | H24: {=MEDIAN(IF($R$11:$R$22="X",H11:H22))} -> 0.1270073 | I24: {=MEDIAN(IF($R$11:$R$22="X",I11:I22))} -> 0.474 | J24: {=MEDIAN(IF($R$11:$R$22="X",J11:J22))} -> 0.030656934 | K24: {=MEDIAN(IF($R$11:$R$22="X",K11:K22))} -> 56.93 | ... Q24: {=MEDIAN(IF($R$11:$R$22="X",Q11:Q22))} -> 40.759494
C25: 25th percentile | D25: {=PERCENTILE(IF($R$11:$R$22="X",D11:D22),0.25)} -> 11400 | E25: {=PERCENTILE(IF($R$11:$R$22="X",E11:E22),0.25)} -> 2.09 | F25: {=PERCENTILE(IF($R$11:$R$22="X",F11:F22),0.25)} -> 0.0212 | G25: {=PERCENTILE(IF($R$11:$R$22="X",G11:G22),0.25)} -> 0.174 | H25: {=PERCENTILE(IF($R$11:$R$22="X",H11:H22),0.25)} -> 0.08277512 | I25: {=PERCENTILE(IF($R$11:$R$22="X",I11:I22),0.25)} -> 0.042 | J25: {=PERCENTILE(IF($R$11:$R$22="X",J11:J22),0.25)} -> 0.018181818 | K25: {=PERCENTILE(IF($R$11:$R$22="X",K11:K22),0.25)} -> 39.95 | ... Q25: {=PERCENTILE(IF($R$11:$R$22="X",Q11:Q22),0.25)} -> 34.123377
C26: 75th percentile | D26: {=PERCENTILE(IF($R$11:$R$22="X",D11:D22),0.75)} -> 130000 | E26: {=PERCENTILE(IF($R$11:$R$22="X",E11:E22),0.75)} -> 11.79 | F26: {=PERCENTILE(IF($R$11:$R$22="X",F11:F22),0.75)} -> 0.0731 | G26: {=PERCENTILE(IF($R$11:$R$22="X",G11:G22),0.75)} -> 2.28 | H26: {=PERCENTILE(IF($R$11:$R$22="X",H11:H22),0.75)} -> 0.19338422 | I26: {=PERCENTILE(IF($R$11:$R$22="X",I11:I22),0.75)} -> 0.5 | J26: {=PERCENTILE(IF($R$11:$R$22="X",J11:J22),0.75)} -> 0.10309278 | K26: {=PERCENTILE(IF($R$11:$R$22="X",K11:K22),0.75)} -> 89.6 | ... Q26: {=PERCENTILE(IF($R$11:$R$22="X",Q11:Q22),0.75)} -> 41.578947
A28: • | C28: McDonald's Valuation
N30: Equity Value | R30: Price per share
C31: McDonald's | D31: Revenue | E31: EBITDA | F31: Net Income | G31: # Shares | H31: Cash | I31: Debt | J31: EV / Revenue | K31: EV / EBITDA | L31: P / Sales | M31: P / E | N31: EV / Revenue | O31: EV / EBITDA | P31: P / Sales | Q31: P / E | R31: EV / Revenue | S31: EV / EBITDA | T31: P / Sales | U31: P / E
C32: Mean | D32: =E10 -> 26.27 | E32: =G10 -> 14.33 | F32: =I10 -> 8.41 | G32: =DCF!R103 -> 712.1 | H32: =DCF!R100/1000 -> 1.047803 | I32: =DCF!R101/1000 -> -49.552872 | J32: =N23 -> 2.7215249 | K32: =O23 -> 18.70176 | L32: =P23 -> 2.2685079 | M32: =Q23 -> 47.108744 | N32: =D32*J32+H32+I32 -> 22.989389 | O32: =K32*E32+H32+I32 -> 219.49115 | P32: =L32*D32 -> 59.593701 | Q32: =M32*F32 -> 396.18454 | R32: =N32*1000/$G32 -> 32.283934 | S32: =O32*1000/$G32 -> 308.2308 | T32: =P32*1000/$G32 -> 83.687265 | U32: =Q32*1000/$G32 -> 556.36082
C33: Median | D33: =D32 -> 26.27 | E33: =E32 -> 14.33 | F33: =F32 -> 8.41 | G33: =G32 -> 712.1 | H33: =H32 -> 1.047803 | I33: =I32 -> -49.552872 | J33: =N24 -> 3.1313869 | K33: =O24 -> 19.019417 | L33: =P24 -> 2.7518248 | M33: =Q24 -> 40.759494 | N33: =D33*J33+H33+I33 -> 33.756464 | O33: =K33*E33+H33+I33 -> 224.04318 | P33: =L33*D33 -> 72.290438 | Q33: =M33*F33 -> 342.78734 | R33: =N33*1000/$G33 -> 47.404106 | S33: =O33*1000/$G33 -> 314.6232 | T33: =P33*1000/$G33 -> 101.51726 | U33: =Q33*1000/$G33 -> 481.37529
C34: 25th percentile | D34: =D33 -> 26.27 | E34: =E33 -> 14.33 | F34: =F33 -> 8.41 | G34: =G33 -> 712.1 | H34: =H33 -> 1.047803 | I34: =I33 -> -49.552872 | J34: =N25 -> 1.2105263 | K34: =O25 -> 14.624277 | L34: =P25 -> 0.75598086 | M34: =Q25 -> 34.123377 | N34: =D34*J34+H34+I34 -> -16.704542 | O34: =K34*E34+H34+I34 -> 161.06083 | P34: =L34*D34 -> 19.859617 | Q34: =M34*F34 -> 286.9776 | R34: =N34*1000/$G34 -> -23.458141 | S34: =O34*1000/$G34 -> 226.17726 | T34: =P34*1000/$G34 -> 27.888804 | U34: =Q34*1000/$G34 -> 403.00182
C35: 75th percentile | D35: =D34 -> 26.27 | E35: =E34 -> 14.33 | F35: =F34 -> 8.41 | G35: =G34 -> 712.1 | H35: =H34 -> 1.047803 | I35: =I34 -> -49.552872 | J35: =N26 -> 4.0391753 | K35: =O26 -> 24.464912 | L35: =P26 -> 3.0226804 | M35: =Q26 -> 41.578947 | N35: =D35*J35+H35+I35 -> 57.604065 | O35: =K35*E35+H35+I35 -> 302.07712 | P35: =L35*D35 -> 79.405814 | Q35: =M35*F35 -> 349.67895 | R35: =N35*1000/$G35 -> 80.893225 | S35: =O35*1000/$G35 -> 424.20604 | T35: =P35*1000/$G35 -> 111.50936 | U35: =Q35*1000/$G35 -> 491.05315

Sheet 52 Week Share Price
C2: Share price
A4: • | C4: McDonald's Valuation
C7: {=_xlfn.STOCKHISTORY("MCD",DATE(2025,1,1),DATE(2025,12,31))} -> Date | D7: Close | F7: Valuation
C8: 45659 | D8: 292.51 | F8: Mean | G8: =AVERAGE(D8:D257) -> 304.5654
C9: 45660 | D9: 294.78 | F9: Median | G9: =MEDIAN(D8:D257) -> 305.54
C10: 45663 | D10: 292.18 | F10: 25th percentile | G10: =PERCENTILE(D8:D257,0.25) -> 299.455
C11: 45664 | D11: 289.34 | F11: 75th percentile | G11: =PERCENTILE(D8:D257,0.75) -> 311.3975
C12: 45665 | D12: 286.9
C13: 45667 | D13: 282.31
C14: 45670 | D14: 283.63
C15: 45671 | D15: 281.58
C16: 45672 | D16: 282.3
C17: 45673 | D17: 279.74
C18: 45674 | D18: 280.95
C19: 45678 | D19: 282.61
C20: 45679 | D20: 281.35
C21: 45680 | D21: 284.43
C22: 45681 | D22: 285.46
C23: 45684 | D23: 293.09
... C257: 46022 | D257: 305.63

Sheet BS
B2: McDonald's Corporation
B3: MCD 580135101 2550707 NYSE Common stock
B4: Source: FactSet Fundamentals
C5: DEC '15 | D5: DEC '16 | E5: DEC '17 | F5: DEC '18 | G5: DEC '19 | H5: DEC '20 | I5: DEC '21 | J5: DEC '22 | K5: DEC '23 | L5: DEC '24
G6: Restate
B7: Assets
B8: Cash & Short-Term Investments | C8: 7074.9332 | D8: 1159.8957 | E8: 2051.7988 | F8: 757.55587 | G8: 800.44544 | H8: 2818.9285 | I8: 4141.0482 | J8: 2420.9885 | K8: 4145.4761 | L8: 1047.803
B9: Cash Only | C9: 7074.9332 | D9: 1159.8957 | E9: 2051.7988 | F9: 757.55587 | G9: 800.44544 | H9: 2818.9285 | I9: 4141.0482 | J9: 2420.9885 | K9: 4145.4761 | L9: 1047.803
B10: Short-Term Receivables | C10: 1195.5261 | D10: 1397.5824 | E10: 1645.7362 | F10: 2135.7652 | G10: 1981.4699 | H10: 1724.7354 | I10: 1646.5002 | J10: 1981.7287 | K10: 2252.2972 | L10: 2301.3037
B11: Accounts Receivables, Net | C11: 1195.5261 | D11: 1397.5824 | E11: 1645.7362 | F11: 2135.7652 | G11: 1981.4699 | H11: 1724.7354 | I11: 1646.5002 | J11: 1981.7287 | K11: 2252.2972 | L11: 2301.3037
B12: Accounts Receivables, Gross | C12: 1195.5261 | D12: 1397.5824 | E12: 1645.7362 | F12: 2135.7652 | G12: 1981.4699 | H12: 1724.7354 | I12: 1646.5002 | J12: 1981.7287 | K12: 2252.2972 | L12: 2301.3037
B13: Inventories | C13: 92.147656 | D13: 55.842618 | E13: 48.967356 | F13: 44.701045 | G13: 44.721604 | H13: 41.76372 | I13: 48.892016 | J13: 48.723354 | K13: 47.797947 | L13: 54.080153
B14: Finished Goods | C14: 92.147656 | D14: 55.842618 | E14: 48.967356 | F14: 44.701045 | G14: 44.721604 | H14: 41.76372 | I14: 48.892016 | J14: 48.723354
B15: Other Current Assets | C15: 514.31464 | D15: 1983.598 | E15: 689.87342 | F15: 607.61929 | G15: 342.98441 | H15: 517.10188 | I15: 449.61309 | J15: 630.96744 | K15: 784.23032 | L15: 1037.1801
B16: Miscellaneous Current Assets | C16: 514.31464 | D16: 1983.598 | E16: 689.87342 | F16: 607.61929 | G16: 342.98441 | H16: 517.10188 | I16: 449.61309 | J16: 630.96744 | K16: 784.23032 | L16: 1037.1801
B17: Total Current Assets | C17: 8876.9216 | D17: 4596.9188 | E17: 4436.3758 | F17: 3545.6414 | G17: 3169.6214 | H17: 5102.5295 | I17: 6286.0535 | J17: 5082.408 | K17: 7229.8015 | L17: 4440.3668
B18: Net Property, Plant & Equipment | C18: 21281.046 | D18: 20154.16 | E18: 18694.454 | F18: 19982.242 | G18: 33337.372 | H18: 31699.481 | I18: 33655.118 | J18: 34049.473 | K18: 34782.059 | L18: 37309.511
B19: Property, Plant & Equipment - Gross | C19: 34697.965 | D19: 32655.511 | E19: 30501.666 | F19: 32536.062 | G19: 46603.208 | H19: 45199.788 | I19: 48776.469 | J19: 50225.626 | K19: 51676.46 | L19: 55544.18
B20: Buildings | C20: 24767.191 | D20: 23898.649 | E20: 22723.268 | F20: 24704.544 | G20: 26378.263 | H20: 25812.921 | I20: 28094.707 | J20: 29445.959 | K20: 30219.165 | L20: 32741.67
B21: Land & Improvements | C21: 5139.0039 | D21: 5181.3227 | E21: 4715.3565 | F21: 4829.9873 | G21: 5368.7306 | H21: 5189.081 | I21: 5704.8893 | J21: 6264.98 | K21: 6410.4469 | L21: 7004.3455
B22: Machinery & Equipment | C22: 4288.4102 | D22: 3101.1141 | E22: 2636.3258 | F22: 2574.1153 | G22: 2667.706 | H22: 2549.1398 | I22: 2666.1977 | J22: 2341.1572 | K22: 2437.6047 | L22: 2497.3442
B23: Other Property, Plant & Equipment | C23: 503.36003 | D23: 474.42523 | E23: 426.71553 | F23: 427.41547 | G23: 374.52116 | H23: 347.34992 | I23: 393.68625 | J23: 399.6252 | K23: 375.14146 | L23: 419.12119
B24: Operating Lease Right-of-Use Assets | G24: 11813.987 | H24: 11301.295 | I24: 11916.989 | J24: 11773.905 | K24: 12234.102 | L24: 12881.699
B25: Accumulated Depreciation | C25: 13416.92 | D25: 12501.351 | E25: 11807.212 | F25: 12553.82 | G25: 13265.835 | H25: 13500.307 | I25: 15121.351 | J25: 16176.154 | K25: 16894.401 | L25: 18234.669
B26: Total Long-Term Investments | C26: 863.94181 | D26: 692.20196 | E26: 1043.5543 | F26: 1055.5045 | G26: 1310.4677 | H26: 1089.4528 | I26: 1264.5973 | J26: 1024.3148 | K26: 1150.7718 | L26: 2655.7218
B27: LT Investment - Affiliate Companies | C27: 729.72475 | D27: 688.21997 | E27: 904.14724 | F27: 1052.1804 | G27: 1131.6704 | H27: 1060.1937 | I27: 1056.2786 | J27: 997.42328 | K27: 977.86632 | L27: 2617.0931
B28: Other Long-Term Investments | C28: 134.21707 | D28: 3.981986 | E28: 139.40706 | F28: 3.324148 | G28: 178.79733 | H28: 29.259123 | I28: 208.31868 | J28: 26.891544 | K28: 172.90545 | L28: 38.628681
B29: Intangible Assets | C29: 2316.3951 | D29: 2215.2169 | E29: 1981.7622 | F29: 2039.5398 | G29: 2977.9956 | H29: 2831.3514 | I29: 3145.8847 | J29: 3527.4771 | K29: 3509.1659 | L29: 3913.0854
B30: Goodwill | C30: 2316.3951 | D30: 2215.2169 | E30: 1981.7622 | F30: 2039.5398 | G30: 2385.2116 | H30: 2266.4378 | I30: 2446.7992 | J30: 2717.6388 | K30: 2752.3651 | L30: 3037.18
B31: Other Intangible Assets | C31: 0 | D31: 0 | E31: 0 | F31: 0 | G31: 592.78397 | H31: 564.91357 | I31: 699.08548 | J31: 809.83836 | K31: 756.80082 | L31: 875.90534
B32: Deferred Tax Assets | C32: 490.47224 | D32: 762.26595 | E32: 722.76816 | F32: 1066.7016 | G32: 1014.6103 | H32: 1745.4947 | I32: 2072.6346 | J32: 2320.9182 | K32: 2736.523 | L32: 3421.5354
B33: Other Assets | C33: 1095.9219 | D33: 992.74712 | E33: 1272.0686 | F33: 1012.8155 | G33: 515.81292 | H33: 543.25528 | I33: 932.64159 | J33: 1252.9398 | K33: 1419.3636 | L33: 1549.9758
B34: Tangible Other Assets | C34: 1095.9219 | D34: 992.74712 | E34: 1272.0686 | F34: 1012.8155 | G34: 515.81292 | H34: 543.25528 | I34: 932.64159 | J34: 1252.9398 | K34: 1419.3636 | L34: 1549.9758
B35: Total Assets | C35: 34924.698 | D35: 29413.511 | E35: 28150.983 | F35: 28702.445 | G35: 42325.88 | H35: 43011.565 | I35: 47356.93 | J35: 47257.531 | K35: 50827.685 | L35: 53290.196
B36: Liabilities & Shareholders' Equity
B37: Current
B38: ST Debt & Curr. Portion LT Debt | C38: 0 | D38: 73.192701 | E38: 0 | F38: 0 | G38: 605.87974 | H38: 2407.0124 | I38: 620.38341 | J38: 619.44249 | K38: 2607.6134 | L38: 614.19602
B39: Accounts Payable | C39: 805.21034 | D39: 716.75754 | E39: 770.15324 | F39: 1056.6417 | G39: 880.35636 | H39: 605.86 | I39: 885.33241 | J39: 918.43522 | K39: 998.41582 | L39: 993.72281
B40: Income Tax Payable | C40: 142.50207 | D40: 253.33018 | E40: 221.35243 | F40: 199.71132 | G40: 295.50112 | H40: 605.69654 | I40: 317.18256 | J40: 257.57788 | K40: 638.30174 | L40: 348.62384
B41: Other Current Liabilities | C41: 1768.296 | D41: 2244.987 | E41: 1415.7229 | F41: 1344.7929 | G41: 1444.098 | H41: 1433.2884 | I41: 1712.0999 | J41: 1767.0649 | K41: 1964.8758 | L41: 1772.0907
...

Sheet IS
B1: McDonald's Corporation (MCD)
B2: $310.45
B5: McDonald's Corporation
B6: MCD 580135101 2550707 NYSE Common stock
B7: Source: FactSet Fundamentals
C8: DEC '15 | D8: DEC '16 | E8: DEC '17 | F8: DEC '18 | G8: DEC '19 | H8: DEC '20 | I8: DEC '21 | J8: DEC '22 | K8: DEC '23 | L8: DEC '24 | M8: SEP '25
M9: LTM
G10: Restate
B11: Sales | C11: 22917 | D11: 22258 | E11: 20232 | F11: 17822 | G11: 19088 | H11: 16849 | I11: 19647 | J11: 22058 | K11: 23581 | L11: 23962 | M11: 23790
B12: Cost of Goods Sold (COGS) incl. D&A | C12: 14089 | D12: 13033 | E12: 10816 | F12: 8679 | G12: 9134 | H12: 8324 | I12: 9063 | J12: 9611 | K12: 10249 | L12: 10463 | M12: 10171
B13: COGS excluding D&A | C13: 12686 | D13: 11662 | E13: 9607 | F13: 7423 | G13: 7689 | H13: 6788 | I13: 7482 | J13: 7831 | K13: 8419 | L13: 8525 | M13: 8200 | O13: Fraction of the year recorded
B14: Depreciation & Amortization Expense | C14: 1403 | D14: 1371 | E14: 1209 | F14: 1256 | G14: 1446 | H14: 1536 | I14: 1580 | J14: 1780 | K14: 1830 | L14: 1939 | M14: 1971 | O14: Calculate with a proportion the total of the year
B15: Depreciation | C15: 1297 | D15: 1257 | E15: 1088 | F15: 1104 | G15: 1244 | H15: 1289 | I15: 1295 | J15: 1383 | K15: 1389 | L15: 1387
B16: Amortization of Intangibles | C16: 106 | D16: 114 | E16: 120 | F16: 152 | G16: 202 | H16: 247 | I16: 285 | J16: 396 | K16: 441 | L16: 552
B17: Gross Income | C17: 8828 | D17: 9225 | E17: 9416 | F17: 9143 | G17: 9954 | H17: 8525 | I17: 10585 | J17: 12447 | K17: 13332 | L17: 13499 | M17: 13619
B18: SG&A Expense | C18: 2195 | D18: 2156 | E18: 1978 | F18: 1865 | G18: 2021 | H18: 2243 | I18: 2316 | J18: 2595 | K18: 2492 | L18: 2535 | M18: 2640
B19: Other SG&A | C19: 2195 | D19: 2156 | E19: 1978 | F19: 1865 | G19: 2021 | H19: 2243 | I19: 2316 | J19: 2595 | K19: 2492 | L19: 2535 | M19: 2640
B20: EBIT (Operating Income) | C20: 6632 | D20: 7069 | E20: 7438 | F20: 7278 | G20: 7932 | H20: 6283 | I20: 8269 | J20: 9852 | K20: 10840 | L20: 10964 | M20: 10978
B21: Nonoperating Income - Net | C21: -2 | D21: 218 | E21: 296 | F21: 356 | G21: 267 | H21: -82 | I21: 118 | J21: -1263 | K21: 861 | L21: 272 | M21: 2168
B22: Nonoperating Interest Income | C22: 9 | D22: 4 | E22: 6 | F22: 3 | G22: 33 | H22: 16 | I22: 8 | J22: 42 | K22: 172 | L22: 95 | M22: 73
B23: Equity in Earnings of Affiliates | C23: -132 | D23: 50 | E23: 163 | F23: 128 | G23: 137 | H23: 103 | I23: 149 | J23: 108 | K23: 142 | L23: 145 | M23: 176
B24: Other Income (Expense) | C24: 121 | D24: 165 | E24: 127 | F24: 224 | G24: 97 | H24: -201 | I24: -39 | J24: -1413 | K24: 547 | L24: 31 | M24: 1919
B25: Interest Expense | C25: 575 | D25: 799 | E25: 816 | F25: 831 | G25: 1057 | H25: 1075 | I25: 1010 | J25: 1236 | K25: 1297 | L25: 1435 | M25: 1460
B26: Gross Interest Expense | C26: 584 | D26: 806 | E26: 821 | F26: 835 | G26: 1063 | H26: 1080 | I26: 1016 | J26: 1245 | K26: 1303 | L26: 1443 | M26: 1460
B27: Interest Capitalized | C27: 8 | D27: 6 | E27: 5 | F27: 5 | G27: 7 | H27: 5 | I27: 6 | J27: 9 | K27: 6 | L27: 8
B28: Unusual Expense - Net | C28: 143 | D28: 281 | E28: -684 | F28: 177 | G28: -21 | H28: -261 | I28: -346 | J28: -94 | K28: 671 | L28: 238 | M28: 2015
B29: Restructuring Expense | C29: 212 | D29: 309 | E29: -623 | F29: 196 | G29: 66 | H29: -235 | I29: -241 | J29: 961 | K29: 335 | L29: 268 | M29: 138
B30: Unrealized Valuation Gain/Loss | C30: 69 | D30: 27 | E30: 61 | F30: 19 | G30: 87 | H30: 26 | I30: 104 | J30: 1055 | K30: -336 | L30: 31 | M30: -1878
B31: Hedges/Derivatives | C31: 69 | D31: 27 | E31: 61 | F31: 19 | G31: 87 | H31: 26 | I31: 104 | J31: 1055 | K31: -336 | L31: 31 | M31: -1878
B32: Pretax Income | C32: 5912 | D32: 6207 | E32: 7601 | F32: 6625 | G32: 7164 | H32: 5387 | I32: 7723 | J32: 7446 | K32: 9733 | L32: 9564 | M32: 9671
B33: Income Taxes | C33: 1827 | D33: 1970 | E33: 2998 | F33: 1604 | G33: 1780 | H33: 1237 | I33: 1339 | J33: 1568 | K33: 1899 | L33: 1961 | M33: 2048
B34: Income Taxes - Current Domestic | C34: 1093 | D34: 1056 | E34: 1951 | F34: 404 | G34: 640 | H34: 591 | I34: 944 | J34: 727 | K34: 1482 | L34: 1554
B35: Income Taxes - Current Foreign | C35: 736 | D35: 1401 | E35: 1079 | F35: 1112 | G35: 1006 | H35: 641 | I35: 757 | J35: 1170 | K35: 1052 | L35: 937
B36: Income Taxes - Deferred Domestic | C36: 3 | D36: -98 | E36: -95 | F36: 139 | G36: 52 | H36: 828 | I36: -170 | J36: -120 | K36: -162 | L36: -89
B37: Income Taxes - Deferred Foreign | C37: -4 | D37: -389 | E37: 63 | F37: -52 | G37: 81 | H37: -822 | I37: -192 | J37: -209 | K37: -472 | L37: -442
B38: Consolidated Net Income | C38: 4084 | D38: 4237 | E38: 4603 | F38: 5022 | G38: 5383 | H38: 4150 | I38: 6384 | J38: 5878 | K38: 7833 | L38: 7602 | M38: 7623
B39: Net Income | C39: 4084 | D39: 4237 | E39: 4603 | F39: 5022 | G39: 5383 | H39: 4150 | I39: 6384 | J39: 5878 | K39: 7833 | L39: 7602 | M39: 7623
B40: Net Income available to Common | C40: 4084 | D40: 4237 | E40: 4603 | F40: 5022 | G40: 5383 | H40: 4150 | I40: 6384 | J40: 5878 | K40: 7833 | L40: 7602 | M40: 7623
B41: Per Share
B42: EPS (recurring) | C42: 4.43 | D42: 5.15 | E42: 5.06 | F42: 6.55 | G42: 7.02 | H42: 5.29 | I42: 8.17 | J42: 7.84 | K42: 11.34 | L42: 10.76 | M42: 12.62
...

Sheet Estimates IS
B1: MCD-US
B2: Income Statement (M)
C3: Dec '20 | D3: Dec '21 | E3: Dec '22 | F3: Dec '23 | G3: Dec '24 | H3: Dec '25E | I3: Dec '26E | J3: Dec '27E | K3: Dec '28E | L3: Dec '29E | M3: Dec '30E
B4: Sales | C4: 15845 | D4: 20830 | E4: 21346 | F4: 23769 | G4: 25127 | H4: 23060 | I4: 24346 | J4: 25549 | K4: 26280 | L4: 26724 | M4: 27928
B5: Cost of Sales | C5: 5759 | D5: 7218 | E5: 6796 | F5: 7668 | G5: 8079 | H5: 7100 | I5: 7503 | J5: 7846 | K5: - | L5: - | M5: -
B6: Gross Income | C6: - | D6: 10463 | E6: 11493 | F6: 13578 | G6: - | H6: 12019 | I6: 12871 | J6: - | K6: - | L6: - | M6: -
B7: Compensation and Benefits | C7: - | D7: - | E7: - | F7: - | G7: - | H7: 2212 | I7: 2328 | J7: - | K7: - | L7: - | M7: -
B8: EBITDA | C8: 7314 | D8: 10722 | E8: 11281 | F8: 12964 | G8: 13602 | H8: 12649 | I8: 13507 | J8: 14343 | K8: 14732 | L8: 15423 | M8: 16266
B9: Operating Income | C9: 5890 | D9: 9158 | E9: 9558 | F9: 11114 | G9: 11634 | H9: 10766 | I9: 11544 | J9: 12260 | K9: 12694 | L9: 13648 | M9: 14487
B10: Pretax Income | C10: 4926 | D10: 7998 | E10: 8595 | F10: 9820 | G10: 10258 | H10: 9456 | I10: 10235 | J10: 10972 | K10: 11366 | L10: 12298 | M10: 13128
B11: Tax Expense | C11: 1163 | D11: 1609 | E11: 1517 | F11: 1915 | G11: 2056 | H11: 2020 | I11: 2158 | J11: 2327 | K11: 2418 | L11: 2582 | M11: 2757
B12: Net Income | C12: 3744 | D12: 6258 | E12: 6892 | F12: 8151 | G12: 8200 | H12: 7465 | I12: 8083 | J12: 8675 | K12: 8988 | L12: 9813 | M12: 10466
B14: % margin EBITDA | H14: =H8/H4 -> 0.54852559 | I14: =I8/I4 -> 0.5547934 | J14: =J8/J4 -> 0.56139184 | K14: =K8/K4 -> 0.56057839 | L14: =L8/L4 -> 0.57712169 | M14: =M8/M4 -> 0.58242624
H16: =H8-H9 -> 1883 | I16: =I8-I9 -> 1963 | J16: =J8-J9 -> 2083 | K16: =K8-K9 -> 2038 | L16: =L8-L9 -> 1775 | M16: =M8-M9 -> 1779
H17: =H16/H4 -> 0.081656548 | I17: =I16/I4 -> 0.080629261 | J17: =J16/J4 -> 0.08152961 | K17: =K16/K4 -> 0.077549467 | L17: =L16/L4 -> 0.066419698 | M17: =M16/M4 -> 0.063699513

Sheet WACC
B3: WACC
B5: WACC = kE*(E/E+D) + kd * D/D+E * (1-tax)
B6: Ke = Rf + Beta * (Rm - Rf)
B7: Rm - Rf = MRP
B9: Rf | C9: 0.0438 | E9: 10-yr treas yield - google
B10: Beta | C10: 0.57 | E10: Factset
B11: MRP | C11: 0.046 | E11: Damodoran
B12: Ke | C12: =C9+C10*C11 -> 0.07002
B14: E | C14: 217140 | E14: Factset
B15: D | C15: =BS!L46 -> 49552.872 | E15: BS
B16: E% | C16: =C14/(SUM(C14:C15)) -> 0.81419499
B17: D% | C17: =C15/SUM(C14:C15) -> 0.18580501
B18: 1-Tax | C18: =1-DCF!M70 -> 0.79823581
B19: Kd | C19: =IS!L25/C15 -> 0.028958968
B21: WACC | C21: =C12*C16+C19*C18*C17 -> 0.061305018
